Workbook
Name Slicer_Sub_Category: #N/A
Name Slicer_Sub_Category1: #N/A
Name Slicer_Year: #N/A

Sheet Dashboard
B8: 2019-20
D10: =VLOOKUP(B8,'Analytics and main data'!$A:$H,2,0) -> 1948083.5 | H10: =VLOOKUP(B8,'Analytics and main data'!$A:$H,3,0) -> 2615319.7 | M10: =VLOOKUP(B8,'Analytics and main data'!$A:$H,5,0) -> 7370383.5 | R10: =VLOOKUP(B8,'Analytics and main data'!$A:$H,6,0) -> 6759434.7 | W10: =VLOOKUP(B8,'Analytics and main data'!$A:$H,8,0) -> 0.078396639
E115: Visit Detailed Report
E121: Source Data

Sheet Report

Sheet Analytics and main data
B1: ANALYTICS : Revenue & Capital: Totals, Deficit/Surplus, Growth % ( ₹ in Crore)
A2: Year | B2: Revenue Receipts (₹Cr) | C2: Revenue Expenditure (₹Cr) | D2: Revenue Deficit (₹Cr) | E2: Capital Receipts (₹Cr) | F2: Capital Expenditure (₹Cr) | G2: Capital Surplus (₹Cr) | H2: Rev Growth % | I2: Trend
A3: 2013-14 | B3: ='Main Data'!C3 -> 1217798.8 | C3: ='Main Data'!C16 -> 1575096.6 | D3: =(Table2[[#This Row],[Revenue Expenditure (₹Cr)]]-Table2[[#This Row],[Revenue Receipts (₹Cr)]])*-1 -> -357297.78 | E3: ='Main Data'!C29 -> 4048883.1 | F3: ='Main Data'!C42 -> 3711135.7 | G3: =Table2[[#This Row],[Capital Receipts (₹Cr)]]-Table2[[#This Row],[Capital Expenditure (₹Cr)]] -> 337747.4 | H3: - | I3: Base year
A4: 2014-15 | B4: ='Main Data'!C4 -> 1328909 | C4: ='Main Data'!C17 -> 1695136.8 | D4: =(Table2[[#This Row],[Revenue Expenditure (₹Cr)]]-Table2[[#This Row],[Revenue Receipts (₹Cr)]])*-1 -> -366227.83 | E4: ='Main Data'!C30 -> 4282482.8 | F4: ='Main Data'!C43 -> 3921706.2 | G4: =Table2[[#This Row],[Capital Receipts (₹Cr)]]-Table2[[#This Row],[Capital Expenditure (₹Cr)]] -> 360776.61 | H4: =(Table2[[#This Row],[Revenue Receipts (₹Cr)]]-B3)/B3 -> 0.091238529 | I4: =IF(Table2[[#This Row],[Revenue Receipts (₹Cr)]]>B3,"▲Growth","▼ Decline") -> ▲Growth
A5: 2015-16 | B5: ='Main Data'!C5 -> 1436160.2 | C5: ='Main Data'!C18 -> 1779528.8 | D5: =(Table2[[#This Row],[Revenue Expenditure (₹Cr)]]-Table2[[#This Row],[Revenue Receipts (₹Cr)]])*-1 -> -343368.59 | E5: ='Main Data'!C31 -> 4400951.2 | F5: ='Main Data'!C44 -> 4063795.2 | G5: =Table2[[#This Row],[Capital Receipts (₹Cr)]]-Table2[[#This Row],[Capital Expenditure (₹Cr)]] -> 337155.96 | H5: =(Table2[[#This Row],[Revenue Receipts (₹Cr)]]-B4)/B4 -> 0.080706251 | I5: =IF(Table2[[#This Row],[Revenue Receipts (₹Cr)]]>B4,"▲Growth","▼ Decline") -> ▲Growth
A6: 2016-17 | B6: ='Main Data'!C6 -> 1615988 | C6: ='Main Data'!C19 -> 1933018.1 | D6: =(Table2[[#This Row],[Revenue Expenditure (₹Cr)]]-Table2[[#This Row],[Revenue Receipts (₹Cr)]])*-1 -> -317030.08 | E6: ='Main Data'!C32 -> 6222850.2 | F6: ='Main Data'!C45 -> 5988306.4 | G6: =Table2[[#This Row],[Capital Receipts (₹Cr)]]-Table2[[#This Row],[Capital Expenditure (₹Cr)]] -> 234543.83 | H6: =(Table2[[#This Row],[Revenue Receipts (₹Cr)]]-B5)/B5 -> 0.12521427 | I6: =IF(Table2[[#This Row],[Revenue Receipts (₹Cr)]]>B5,"▲Growth","▼ Decline") -> ▲Growth
A7: 2017-18 | B7: ='Main Data'!C7 -> 1691143.1 | C7: ='Main Data'!C20 -> 2140084.5 | D7: =(Table2[[#This Row],[Revenue Expenditure (₹Cr)]]-Table2[[#This Row],[Revenue Receipts (₹Cr)]])*-1 -> -448941.43 | E7: ='Main Data'!C33 -> 6724689.2 | F7: ='Main Data'!C46 -> 6279856.8 | G7: =Table2[[#This Row],[Capital Receipts (₹Cr)]]-Table2[[#This Row],[Capital Expenditure (₹Cr)]] -> 444832.38 | H7: =(Table2[[#This Row],[Revenue Receipts (₹Cr)]]-B6)/B6 -> 0.046507227 | I7: =IF(Table2[[#This Row],[Revenue Receipts (₹Cr)]]>B6,"▲Growth","▼ Decline") -> ▲Growth
A8: 2018-19 | B8: ='Main Data'!C8 -> 1806462.9 | C8: ='Main Data'!C21 -> 2261570.8 | D8: =(Table2[[#This Row],[Revenue Expenditure (₹Cr)]]-Table2[[#This Row],[Revenue Receipts (₹Cr)]])*-1 -> -455107.9 | E8: ='Main Data'!C34 -> 6883718.4 | F8: ='Main Data'!C47 -> 6519135.6 | G8: =Table2[[#This Row],[Capital Receipts (₹Cr)]]-Table2[[#This Row],[Capital Expenditure (₹Cr)]] -> 364582.81 | H8: =(Table2[[#This Row],[Revenue Receipts (₹Cr)]]-B7)/B7 -> 0.068190451 | I8: =IF(Table2[[#This Row],[Revenue Receipts (₹Cr)]]>B7,"▲Growth","▼ Decline") -> ▲Growth
A9: 2019-20 | B9: ='Main Data'!C9 -> 1948083.5 | C9: ='Main Data'!C22 -> 2615319.7 | D9: =(Table2[[#This Row],[Revenue Expenditure (₹Cr)]]-Table2[[#This Row],[Revenue Receipts (₹Cr)]])*-1 -> -667236.14 | E9: ='Main Data'!C35 -> 7370383.5 | F9: ='Main Data'!C48 -> 6759434.7 | G9: =Table2[[#This Row],[Capital Receipts (₹Cr)]]-Table2[[#This Row],[Capital Expenditure (₹Cr)]] -> 610948.82 | H9: =(Table2[[#This Row],[Revenue Receipts (₹Cr)]]-B8)/B8 -> 0.078396639 | I9: =IF(Table2[[#This Row],[Revenue Receipts (₹Cr)]]>B8,"▲Growth","▼ Decline") -> ▲Growth
A10: 2020-21 | B10: ='Main Data'!C10 -> 1864513.5 | C10: ='Main Data'!C23 -> 3314851.9 | D10: =(Table2[[#This Row],[Revenue Expenditure (₹Cr)]]-Table2[[#This Row],[Revenue Receipts (₹Cr)]])*-1 -> -1450338.4 | E10: ='Main Data'!C36 -> 8230730.1 | F10: ='Main Data'!C49 -> 6777429.7 | G10: =Table2[[#This Row],[Capital Receipts (₹Cr)]]-Table2[[#This Row],[Capital Expenditure (₹Cr)]] -> 1453300.4 | H10: =(Table2[[#This Row],[Revenue Receipts (₹Cr)]]-B9)/B9 -> -0.042898602 | I10: =IF(Table2[[#This Row],[Revenue Receipts (₹Cr)]]>B9,"▲Growth","▼ Decline") -> ▼ Decline
A11: 2021-22 | B11: ='Main Data'!C11 -> 2436421.5 | C11: ='Main Data'!C24 -> 3468188.8 | D11: =(Table2[[#This Row],[Revenue Expenditure (₹Cr)]]-Table2[[#This Row],[Revenue Receipts (₹Cr)]])*-1 -> -1031767.3 | E11: ='Main Data'!C37 -> 8288738 | F11: ='Main Data'!C50 -> 7445313 | G11: =Table2[[#This Row],[Capital Receipts (₹Cr)]]-Table2[[#This Row],[Capital Expenditure (₹Cr)]] -> 843424.92 | H11: =(Table2[[#This Row],[Revenue Receipts (₹Cr)]]-B10)/B10 -> 0.30673311 | I11: =IF(Table2[[#This Row],[Revenue Receipts (₹Cr)]]>B10,"▲Growth","▼ Decline") -> ▲Growth
A12: 2022-23 | B12: ='Main Data'!C12 -> 2713267.2 | C12: ='Main Data'!C25 -> 3783698.5 | D12: =(Table2[[#This Row],[Revenue Expenditure (₹Cr)]]-Table2[[#This Row],[Revenue Receipts (₹Cr)]])*-1 -> -1070431.3 | E12: ='Main Data'!C38 -> 8947200.1 | F12: ='Main Data'!C51 -> 7966516.6 | G12: =Table2[[#This Row],[Capital Receipts (₹Cr)]]-Table2[[#This Row],[Capital Expenditure (₹Cr)]] -> 980683.53 | H12: =(Table2[[#This Row],[Revenue Receipts (₹Cr)]]-B11)/B11 -> 0.11362801 | I12: =IF(Table2[[#This Row],[Revenue Receipts (₹Cr)]]>B11,"▲Growth","▼ Decline") -> ▲Growth
A13: 2023-24 | B13: ='Main Data'!C13 -> 3088174.6 | C13: ='Main Data'!C26 -> 3854082.2 | D13: =(Table2[[#This Row],[Revenue Expenditure (₹Cr)]]-Table2[[#This Row],[Revenue Receipts (₹Cr)]])*-1 -> -765907.57 | E13: ='Main Data'!C39 -> 9322304.2 | F13: ='Main Data'!C52 -> 8460982.9 | G13: =Table2[[#This Row],[Capital Receipts (₹Cr)]]-Table2[[#This Row],[Capital Expenditure (₹Cr)]] -> 861321.3 | H13: =(Table2[[#This Row],[Revenue Receipts (₹Cr)]]-B12)/B12 -> 0.13817564 | I13: =IF(Table2[[#This Row],[Revenue Receipts (₹Cr)]]>B12,"▲Growth","▼ Decline") -> ▲Growth
A14: RE 2024-25 | B14: ='Main Data'!C14 -> 3485869.3 | C14: ='Main Data'!C27 -> 4096607.1 | D14: =(Table2[[#This Row],[Revenue Expenditure (₹Cr)]]-Table2[[#This Row],[Revenue Receipts (₹Cr)]])*-1 -> -610737.78 | E14: ='Main Data'!C40 -> 9929531.9 | F14: ='Main Data'!C53 -> 9500416.3 | G14: =Table2[[#This Row],[Capital Receipts (₹Cr)]]-Table2[[#This Row],[Capital Expenditure (₹Cr)]] -> 429115.6 | H14: =(Table2[[#This Row],[Revenue Receipts (₹Cr)]]-B13)/B13 -> 0.12877984 | I14: =IF(Table2[[#This Row],[Revenue Receipts (₹Cr)]]>B13,"▲Growth","▼ Decline") -> ▲Growth
A15: BE 2025-26 | B15: ='Main Data'!C15 -> 3835268.5 | C15: ='Main Data'!C28 -> 4359702.4 | D15: =(Table2[[#This Row],[Revenue Expenditure (₹Cr)]]-Table2[[#This Row],[Revenue Receipts (₹Cr)]])*-1 -> -524433.89 | E15: ='Main Data'!C41 -> 10760099 | F15: ='Main Data'!C54 -> 10293122 | G15: =Table2[[#This Row],[Capital Receipts (₹Cr)]]-Table2[[#This Row],[Capital Expenditure (₹Cr)]] -> 466976.28 | H15: =(Table2[[#This Row],[Revenue Receipts (₹Cr)]]-B14)/B14 -> 0.10023303 | I15: =IF(Table2[[#This Row],[Revenue Receipts (₹Cr)]]>B14,"▲Growth","▼ Decline") -> ▲Growth
A16: Total | B16: =SUM(B3:B15) -> 28468060 | C16: =SUM(C3:C15) -> 36876886 | D16: =SUM(D3:D15) -> -8408826.1 | E16: =SUM(E3:E15) -> 95412561 | F16: =SUM(F3:F15) -> 87687152 | G16: =SUM(G3:G15) -> 7725409.9 | H16: ="-" -> - | I16: ="13 years " -> 13 years

Sheet  Receipts vs Expenditure
A1: Pivot 1 - Receipts vs Expenditure Over Time (₹ Crore)
A2: Years | B2: Revenue Receipts (₹Crore) | C2: Revenue Expenditure (₹Crore) | D2: Capital Expenditure (₹Crore) | E2: Capital Receipts (₹Crore)
A3: 2013-14 | B3: 1217798.8 | C3: 1575096.6 | D3: 3711135.7 | E3: 4048883.1
A4: 2014-15 | B4: 1328909 | C4: 1695136.8 | D4: 3921706.2 | E4: 4282482.8
A5: 2015-16 | B5: 1436160.2 | C5: 1779528.8 | D5: 4063795.2 | E5: 4400951.2
A6: 2016-17 | B6: 1615988 | C6: 1933018.1 | D6: 5988306.4 | E6: 6222850.2 | AX6: Revenue Receipts (₹Crore) | AY6: =VLOOKUP(Dashboard!$B$8,'Analytics and main data'!$A:$H,2,0) -> 1948083.5
A7: 2017-18 | B7: 1691143.1 | C7: 2140084.5 | D7: 6279856.8 | E7: 6724689.2 | AX7: Revenue Expenditure (₹Crore) | AY7: =VLOOKUP(Dashboard!$B$8,'Analytics and main data'!$A:$H,3,0) -> 2615319.7
A8: 2018-19 | B8: 1806462.9 | C8: 2261570.8 | D8: 6519135.6 | E8: 6883718.4 | AX8: Capital Receipts (₹Crore) | AY8: =VLOOKUP(Dashboard!$B$8,'Analytics and main data'!$A:$H,5,0) -> 7370383.5
A9: 2019-20 | B9: 1948083.5 | C9: 2615319.7 | D9: 6759434.7 | E9: 7370383.5 | AX9: Capital Expenditure (₹Crore) | AY9: =VLOOKUP(Dashboard!$B$8,'Analytics and main data'!$A:$H,6,0) -> 6759434.7
A10: 2020-21 | B10: 1864513.5 | C10: 3314851.9 | D10: 6777429.7 | E10: 8230730.1
A11: 2021-22 | B11: 2436421.5 | C11: 3468188.8 | D11: 7445313 | E11: 8288738
A12: 2022-23 | B12: 2713267.2 | C12: 3783698.5 | D12: 7966516.6 | E12: 8947200.1
A13: 2023-24 | B13: 3088174.6 | C13: 3854082.2 | D13: 8460982.9 | E13: 9322304.2
A14: BE 2025-26 | B14: 3835268.5 | C14: 4359702.4 | D14: 10293122 | E14: 10760099
A15: RE 2024-25 | B15: 3485869.3 | C15: 4096607.1 | D15: 9500416.3 | E15: 9929531.9
A16: Grand Total | B16: 28468060 | C16: 36876886 | D16: 87687152 | E16: 95412561

Sheet deficit and surplus
A1: Row Labels | B1: Revenue Deficit(₹Cr) | C1: Capital Surplus(₹Cr)
A2: 2013-14 | B2: -357297.78 | C2: 337747.4
A3: 2014-15 | B3: -366227.83 | C3: 360776.61
A4: 2015-16 | B4: -343368.59 | C4: 337155.96 | G4: Row Labels | H4: Sum of Revenue Deficit (₹Cr) | I4: Sum of Capital Surplus (₹Cr)
A5: 2016-17 | B5: -317030.08 | C5: 234543.83 | G5: 2013-14 | H5: -357297.78 | I5: 337747.4
A6: 2017-18 | B6: -448941.43 | C6: 444832.38 | G6: 2014-15 | H6: -366227.83 | I6: 360776.61
A7: 2018-19 | B7: -455107.9 | C7: 364582.81 | G7: 2015-16 | H7: -343368.59 | I7: 337155.96
A8: 2019-20 | B8: -667236.14 | C8: 610948.82 | G8: 2016-17 | H8: -317030.08 | I8: 234543.83
A9: 2020-21 | B9: -1450338.4 | C9: 1453300.4 | G9: 2017-18 | H9: -448941.43 | I9: 444832.38
A10: 2021-22 | B10: -1031767.3 | C10: 843424.92 | G10: 2018-19 | H10: -455107.9 | I10: 364582.81
A11: 2022-23 | B11: -1070431.3 | C11: 980683.53 | G11: 2019-20 | H11: -667236.14 | I11: 610948.82
A12: 2023-24 | B12: -765907.57 | C12: 861321.3 | G12: 2020-21 | H12: -1450338.4 | I12: 1453300.4
A13: BE 2025-26 | B13: -524433.89 | C13: 466976.28 | G13: 2021-22 | H13: -1031767.3 | I13: 843424.92
A14: RE 2024-25 | B14: -610737.78 | C14: 429115.6 | G14: 2022-23 | H14: -1070431.3 | I14: 980683.53
A15: Grand Total | B15: -8408826.1 | C15: 7725409.9 | G15: 2023-24 | H15: -765907.57 | I15: 861321.3
G16: BE 2025-26 | H16: -524433.89 | I16: 466976.28
G17: RE 2024-25 | H17: -610737.78 | I17: 429115.6

Sheet Tax Revenue composition
B1: Column Labels
A2: Year | B2: CGST | C2: Corporation Tax | D2: Customs | E2: GST Compensation Cess | F2: IGST | G2: Income Tax (excl. Corp Tax) | H2: Securities Transaction Tax | I2: Service Tax | J2: Union Excise Duties | K2: Grand Total
A3: (2013-14) | B3: 0 | C3: 394677.85 | D3: 172085.42 | E3: 0 | F3: 0 | G3: 237817.23 | H3: 5017.5 | I3: 154778.12 | J3: 169455.14 | K3: 1133831.3
A4: (2014-15) | B4: 0 | C4: 428924.74 | D4: 188016.19 | E4: 0 | F4: 0 | G4: 258325.65 | H4: 7398.15 | I4: 167969.04 | J4: 188127.6 | K4: 1238761.4
A5: ( 2015-16) | B5: 0 | C5: 453228.33 | D5: 210338 | E5: 0 | F5: 0 | G5: 280322.5 | H5: 7350.12 | I5: 211414.25 | J5: 287148.55 | K5: 1449801.8
A6: (2016-17) | B6: 0 | C6: 484923.86 | D6: 225370.34 | E6: 0 | F6: 0 | G6: 340504.5 | H6: 8998.12 | I6: 254498.74 | J6: 380495.43 | K6: 1694791
A7: (2017-18) | B7: 203261.4 | C7: 571201.87 | D7: 129029.92 | E7: 62611.59 | F7: 176688.44 | G7: 408091.43 | H7: 11881.4 | I7: 81228.07 | J7: 258635.93 | K7: 1902630
A8: ( 2018-19) | B8: 457534.01 | C8: 663571.62 | D8: 117812.85 | E8: 95080.71 | F8: 28944.58 | G8: 461487.51 | H8: 11527.5 | I8: 6903.62 | J8: 230992.59 | K8: 2073855
A9: (2019-20) | B9: 494070.6 | C9: 556875.55 | D9: 109282.54 | E9: 95553.09 | F9: 9125.21 | G9: 480348.14 | H9: 12374.23 | I9: 6029.11 | J9: 239452.43 | K9: 2003110.9
A10: (2020-21) | B10: 456333.97 | C10: 457718.97 | D10: 134750.39 | E10: 85191.91 | F10: 7251.43 | G10: 470391.24 | H10: 16926.99 | I10: 1614.84 | J10: 389667.08 | K10: 2019846.8
A11: (2021-22) | B11: 591226.14 | C11: 712037.33 | D11: 199728.3 | E11: 104768.66 | F11: 2119.08 | G11: 673100.48 | H11: 23191.03 | I11: 1011.82 | J11: 390808.07 | K11: 2697990.9
A12: (2022-23) | B12: 718521.75 | C12: 825833.64 | D12: 213372.09 | E12: 125862.41 | F12: 4748.29 | G12: 808221.32 | H12: 25085.37 | I12: 430.77 | J12: 319000.11 | K12: 3041075.8
A13: (2023-24) | B13: 820622.09 | C13: 911055.01 | D13: 233118.97 | E13: 141436.16 | F13: -4850.43 | G13: 1010947.8 | H13: 33777.78 | I13: 424.96 | J13: 305362.18 | K13: 3451894.5
A14: ( RE 2024-25) | B14: 908459 | C14: 980000 | D14: 235000 | E14: 153440 | F14: 0 | G14: 1199300 | H14: 55000 | I14: 100 | J14: 305000 | K14: 3836299
A15: ( BE 2025-26) | B15: 1010890 | C15: 1082000 | D15: 240000 | E15: 167110 | F15: 0 | G15: 1357000 | H15: 78000 | I15: 100 | J15: 317000 | K15: 4252100

Sheet  Defence spending
B1: Column Labels
A2: Year | B2: Defence Services | C2: Air Force | D2: Army | E2: Navy | F2: R&D | G2: Grand Total
A3: (2013-14) | B3: 79125.05 | C3: 20160.27 | D3: 87750.54 | E3: 13472.26 | F3: 5696.32 | G3: 206204.44
A4: (2014-15) | B4: 81886.98 | C4: 22685.3 | D4: 99321.39 | E4: 14352 | F4: 6237.08 | G4: 224482.75
A5: (2015-16) | B5: 79958.32 | C5: 21848.9 | D5: 105994.58 | E5: 15320.81 | F5: 6183.9 | G5: 229306.51
A6: (2016-17) | B6: 86370.92 | C6: 25228.14 | D6: 120374.48 | E6: 17469.27 | F6: 6963.69 | G6: 256406.5
A7: (2017-18) | B7: 90445.24 | C7: 28418.8 | D7: 135362.36 | E7: 19344.87 | F7: 8033.79 | G7: 281605.06
A8: (2018-19) | B8: 95230.59 | C8: 29370.54 | D8: 141829.61 | E8: 21738.88 | F8: 8431.44 | G8: 296601.06
A9: (2019-20) | B9: 111092.43 | C9: 31528.49 | D9: 146821.92 | E9: 23087.69 | F9: 9086.14 | G9: 321616.67
A10: (2020-21) | B10: 134304.92 | C10: 34615.96 | D10: 145181.03 | E10: 24710.34 | F10: 8350.77 | G10: 347163.02
A11: (2021-22) | B11: 137986.97 | C11: 35687.93 | D11: 161728.27 | E11: 24426.52 | F11: 8406.22 | G11: 368235.91
A12: (2022-23) | B12: 142940.01 | C12: 47455.55 | D12: 175666.05 | E12: 31343.6 | F12: 9407.79 | G12: 406813
A13: (2023-24) | B13: 154256.28 | C13: 54742.33 | D13: 197020.12 | E13: 35147.8 | F13: 10427.48 | G13: 451594.01
A14: (RE 2024-25) | B14: 159500 | C14: 51876.77 | D14: 204628.97 | E14: 36557.31 | F14: 11330.01 | G14: 463893.06
A15: (BE 2025-26) | B15: 180000 | C15: 55000 | D15: 212030.78 | E15: 39019.8 | F15: 12193 | G15: 498243.58

Sheet Capital Expenditure breakdown
B3: Column Labels | H3: Row Labels | I3: (2023-24)
B4: Capital Expenditure | E4: Capital Expenditure Total | F4: Grand Total | H4: Economic Services | I4: 534009.12
A5: Year | B5: Economic Services | C5: General Services | D5: Social Services | H5: Capital - Civil Aviation | I5: 741.31
A6: (2013-14) | B6: 213379.83 | C6: 167025.27 | D6: 3386.56 | E6: 383791.66 | F6: 383791.66 | H6: Capital - Energy | I6: 6999.23
A7: (2014-15) | B7: 209263.81 | C7: 171882.24 | D7: 4347.51 | E7: 385493.56 | F7: 385493.56 | H7: Capital - Indian Railways (Commercial) | I7: 242537.91
A8: (2015-16) | B8: 450985.07 | C8: 171420.58 | D8: 4903.24 | E8: 627308.89 | F8: 627308.89 | H8: Capital - Industry & Minerals | I8: 6708.31 | K8: Row Labels | L8: Sum of 2023-24
A9: (2016-17) | B9: 400976.72 | C9: 185553.97 | D9: 4537.33 | E9: 591068.02 | F9: 591068.02 | H9: Capital - Roads & Bridges | I9: 269865.27 | K9: Civil Aviation | L9: 741.31
A10: (2017-18) | B10: 595292.47 | C10: 196798 | D10: 8749.6 | E10: 800840.07 | F10: 800840.07 | H10: Capital - Science, Tech & Environment | I10: 7157.09 | K10: Energy | L10: 6999.23
A11: (2018-19) | B11: 781370.21 | C11: 208151.98 | D11: 9148.85 | E11: 998671.04 | F11: 998671.04 | H11: Grand Total | I11: 534009.12 | K11: Indian Railways (Commercial) | L11: 242537.91
A12: (2019-20) | B12: 708946.87 | C12: 235899.85 | D12: 9492.19 | E12: 954338.91 | F12: 954338.91 | K12: Industry & Minerals | L12: 6708.31
A13: (2020-21) | B13: 532931.15 | C13: 277050.57 | D13: 7109.9 | E13: 817091.62 | F13: 817091.62 | K13: Roads & Bridges | L13: 269865.27
A14: (2021-22) | B14: 1059245.3 | C14: 291763.87 | D14: 9445.11 | E14: 1360454.3 | F14: 1360454.3 | K14: Science, Tech & Environment | L14: 7157.09
A15: (2022-23) | B15: 1208979.9 | C15: 304127.5 | D15: 12166.45 | E15: 1525273.9 | F15: 1525273.9
A16: (2023-24) | B16: 1697221.5 | C16: 331743.93 | D16: 8587.45 | E16: 2037552.9 | F16: 2037552.9
A17: (RE 2024-25) | B17: 1720934.8 | C17: 342091.24 | D17: 11503.31 | E17: 2074529.3 | F17: 2074529.3
A18: (BE 2025-26) | B18: 1899102.4 | C18: 389088.88 | D18: 11186.3 | E18: 2299377.6 | F18: 2299377.6

Sheet debt
B4: Column Labels | M4: Year | N4: Total Public Debt | O4: Total Public Debt Repayment | P4: Net New Debt
B5: Capital Receipts | G5: Capital Receipts Total | H5: Grand Total | M5: 2013-14 | N5: 3994966 | O5: 3511291 | P5: 483675
A6: Year | B6: 182 Days Treasury Bills | C6: 364 Days Treasury Bills | D6: 91 Days Treasury Bills | E6: External Debt | F6: Market Loans | M6: 2014-15 | N6: 4218196 | O6: 3707700 | P6: 510496
A7: (2013-14) | B7: 137520.26 | C7: 136956.26 | D7: 580087.59 | E7: 25416.23 | F7: 563674.67 | G7: 1443655 | H7: 1443655 | M7: 2015-16 | N7: 4316950 | O7: 3737657 | P7: 579293
A8: (2014-15) | B8: 147608.18 | C8: 149200.68 | D8: 670312.98 | E8: 33533.89 | F8: 592000 | G8: 1592655.7 | H8: 1592655.7 | M8: 2016-17 | N8: 6134137 | O8: 5678823 | P8: 455314
A9: (2015-16) | B9: 162188.61 | C9: 154033.2 | D9: 686666.71 | E9: 36053.72 | F9: 585000 | G9: 1623942.2 | H9: 1623942.2 | M9: 2017-18 | N9: 6554002 | O9: 5872605 | P9: 681397
A10: (2016-17) | B10: 174035.07 | C10: 142525.75 | D10: 664567.49 | E10: 44191.49 | F10: 583045 | G10: 1608364.8 | H10: 1608364.8 | M10: 2018-19 | N10: 6758482 | O10: 6064945 | P10: 693537
A11: (2017-18) | B11: 185416.61 | C11: 159685 | D11: 774059.95 | E11: 48516.74 | F11: 588000 | G11: 1755678.3 | H11: 1755678.3 | M11: 2019-20 | N11: 7301387 | O11: 6326549 | P11: 974838
A12: (2018-19) | B12: 258020.06 | C12: 208896 | D12: 660165.24 | E12: 50609.44 | F12: 571000 | G12: 1748690.7 | H12: 1748690.7 | M12: 2020-21 | N12: 8162910 | O12: 6184635 | P12: 1978275
A13: (2019-20) | B13: 321689.3 | C13: 217670 | D13: 639472.68 | E13: 63180.3 | F13: 710000 | G13: 1952012.3 | H13: 1952012.3 | M13: 2021-22 | N13: 8249152 | O13: 6645468 | P13: 1603684
A14: (2020-21) | B14: 488606.87 | C14: 458240 | D14: 743488.03 | E14: 123937.57 | F14: 1260115.7 | G14: 3074388.2 | H14: 3074388.2 | M14: 2022-23 | N14: 8864893 | O14: 7199701 | P14: 1665192
A15: (2021-22) | B15: 465678.81 | C15: 407796.43 | D15: 847904.18 | E15: 86664.57 | F15: 968381.54 | G15: 2776425.5 | H15: 2776425.5 | M15: 2023-24 | N15: 9160050 | O15: 7462493 | P15: 1697557
A16: (2022-23) | B16: 549240.87 | C16: 445283.5 | D16: 715950.53 | E16: 93731.28 | F16: 1421000 | G16: 3225206.2 | H16: 3225206.2 | M16: RE 2024-25 | N16: 9693665 | O16: 8407558 | P16: 1286107
A17: (2023-24) | B17: 571191.61 | C17: 457486.99 | D17: 644427.47 | E17: 120429.2 | F17: 1543000 | G17: 3336535.3 | H17: 3336535.3 | M17: BE 2025-26 | N17: 10566349 | O17: 9038648 | P17: 1527701
A18: (RE 2024-25) | B18: 394007.06 | C18: 360809.92 | D18: 747644.75 | E18: 107711.53 | F18: 1400697.4 | G18: 3010870.7 | H18: 3010870.7
A19: (BE 2025-26) | B19: 484082.34 | C19: 360809.92 | D19: 606191.25 | E19: 111013.36 | F19: 1482000 | G19: 3044096.9 | H19: 3044096.9

Sheet NTR
A2: Category | B2: Revenue Receipts
A4: Row Labels | B4: 2013-14 | C4: 2020-21 | D4: 2025-26
A5: Dividends and Profits | B5: 90434.52 | C5: 96877.75 | D5: 325000
A6: Interest Receipts | B6: 43991.35 | C6: 59528.76 | D6: 90237.98
A7: Economic Services | B7: 226411.08 | C7: 228124.6 | D7: 481884.77
A8: General Services | B8: 28956.11 | C8: 39565.88 | D8: 72257.03
A9: Other Communication Services | B9: 40113.76 | C9: 45500.65 | D9: 82442.84
A10: Postal Receipts | B10: 10730.42 | C10: 10632.31 | D10: 12487.11
A11: Grand Total | B11: 440637.24 | C11: 480229.95 | D11: 1064309.7

Sheet Main Data
A1: Consolidated Fund of India (₹ in Crore)
A2: Category | B2: Year | C2: Amount (₹ Crore) | D2: Sub-Category Label
A3: Total Revenue Receipts | B3: 2013-14 | C3: 1217798.8 | D3: Total Revenue Receipts
A4: Revenue Receipts | B4: 2014-15 | C4: 1328909 | D4: Total Revenue Receipts
A5: Revenue Receipts | B5: 2015-16 | C5: 1436160.2 | D5: Total Revenue Receipts
A6: Revenue Receipts | B6: 2016-17 | C6: 1615988 | D6: Total Revenue Receipts
A7: Revenue Receipts | B7: 2017-18 | C7: 1691143.1 | D7: Total Revenue Receipts
A8: Revenue Receipts | B8: 2018-19 | C8: 1806462.9 | D8: Total Revenue Receipts
A9: Revenue Receipts | B9: 2019-20 | C9: 1948083.5 | D9: Total Revenue Receipts
A10: Revenue Receipts | B10: 2020-21 | C10: 1864513.5 | D10: Total Revenue Receipts
A11: Revenue Receipts | B11: 2021-22 | C11: 2436421.5 | D11: Total Revenue Receipts
A12: Revenue Receipts | B12: 2022-23 | C12: 2713267.2 | D12: Total Revenue Receipts
A13: Revenue Receipts | B13: 2023-24 | C13: 3088174.6 | D13: Total Revenue Receipts
A14: Revenue Receipts | B14: RE 2024-25 | C14: 3485869.3 | D14: Total Revenue Receipts
... A54: Capital Expenditure | B54: BE 2025-26 | C54: 10293122 | D54: Total Capital Expenditure

Sheet Sub Components
A1: SUB-COMPONENTS-Consolidated Fund of India (₹ in Crore)
A2: Statement | B2: Category | C2: Sub-Category | D2: Line Item | E2: 2013-14 | F2: 2014-15 | G2: 2015-16 | H2: 2016-17 | I2: 2017-18 | J2: 2018-19 | K2: 2019-20 | L2: 2020-21 | M2: 2021-22 | N2: 2022-23 | O2: 2023-24 | P2: RE 2024-25 | Q2: BE 2025-26
A3: Revenue Receipts | B3: Revenue Receipts | C3: TOTAL | D3: Total Revenue Receipts | E3: ='[1]revenue receipt'!B120 -> 1217798.8 | F3: ='[1]revenue receipt'!C120 -> 1328909 | G3: ='[1]revenue receipt'!D120 -> 1436160.2 | H3: ='[1]revenue receipt'!E120 -> 1615988 | I3: ='[1]revenue receipt'!F120 -> 1691143.1 | J3: ='[1]revenue receipt'!G120 -> 1806462.9 | K3: ='[1]revenue receipt'!H120 -> 1948083.5 | L3: ='[1]revenue receipt'!I120 -> 1864513.5 | ... Q3: ='[1]revenue receipt'!N120 -> 3835268.5
A4: Revenue Receipts | B4: Revenue Receipts | C4: Tax Revenue | D4: Tax Revenue of the Central Govt | E4: ='[1]revenue receipt'!B32 -> 820765.89 | F4: ='[1]revenue receipt'!C32 -> 907327.3 | G4: ='[1]revenue receipt'!D32 -> 949698.13 | H4: ='[1]revenue receipt'!E32 -> 1107967.7 | I4: ='[1]revenue receipt'!F32 -> 1246178.2 | J4: ='[1]revenue receipt'!G32 -> 1319011.3 | K4: ='[1]revenue receipt'!H32 -> 1359382.3 | L4: ='[1]revenue receipt'!I32 -> 1432107.1 | ... Q4: ='[1]revenue receipt'!N32 -> 2847788.9
A5: Revenue Receipts | B5: Revenue Receipts | C5: Tax Revenue - Gross | D5: Gross Tax Revenue | E5: ='[1]revenue receipt'!B30 -> 1138995.5 | F5: ='[1]revenue receipt'!C30 -> 1245135.8 | G5: ='[1]revenue receipt'!D30 -> 1455891.1 | H5: ='[1]revenue receipt'!E30 -> 1715968 | I5: ='[1]revenue receipt'!F30 -> 1919183.5 | J5: ='[1]revenue receipt'!G30 -> 2080465.4 | K5: ='[1]revenue receipt'!H30 -> 2010059.3 | L5: ='[1]revenue receipt'!I30 -> 2027103.8 | ... Q5: ='[1]revenue receipt'!N30 -> 4270233
A6: Revenue Receipts | B6: Revenue Receipts | C6: Tax Revenue - Gross | D6: States' Share (Devolution) | E6: ='[1]revenue receipt'!B31 -> 318229.58 | F6: ='[1]revenue receipt'!C31 -> 337808.45 | G6: ='[1]revenue receipt'!D31 -> 506192.96 | H6: ='[1]revenue receipt'!E31 -> 608000.31 | I6: ='[1]revenue receipt'!F31 -> 673005.29 | J6: ='[1]revenue receipt'!G31 -> 761454.15 | K6: ='[1]revenue receipt'!H31 -> 650677.05 | L6: ='[1]revenue receipt'!I31 -> 594996.76 | ... Q6: ='[1]revenue receipt'!N31 -> 1422444.1
A7: Revenue Receipts | B7: Revenue Receipts | C7: Tax Revenue - GST | D7: GST (Total) | E7: ='[1]revenue receipt'!B4 -> 0 | F7: ='[1]revenue receipt'!C4 -> 0 | G7: ='[1]revenue receipt'!D4 -> 0 | H7: ='[1]revenue receipt'!E4 -> 0 | I7: ='[1]revenue receipt'!F4 -> 444196.53 | J7: ='[1]revenue receipt'!G4 -> 584337.5 | K7: ='[1]revenue receipt'!H4 -> 601783.88 | L7: ='[1]revenue receipt'!I4 -> 551541.51 | ... Q7: ='[1]revenue receipt'!N4 -> 1183355
A8: Revenue Receipts | B8: Revenue Receipts | C8: Tax Revenue - GST | D8: CGST | E8: ='[1]revenue receipt'!B5 -> 0 | F8: ='[1]revenue receipt'!C5 -> 0 | G8: ='[1]revenue receipt'!D5 -> 0 | H8: ='[1]revenue receipt'!E5 -> 0 | I8: ='[1]revenue receipt'!F5 -> 203261.4 | J8: ='[1]revenue receipt'!G5 -> 457534.01 | K8: ='[1]revenue receipt'!H5 -> 494070.6 | L8: ='[1]revenue receipt'!I5 -> 456333.97 | ... Q8: ='[1]revenue receipt'!N5 -> 1010890
A9: Revenue Receipts | B9: Revenue Receipts | C9: Tax Revenue - GST | D9: IGST | E9: ='[1]revenue receipt'!B7 -> 0 | F9: ='[1]revenue receipt'!C7 -> 0 | G9: ='[1]revenue receipt'!D7 -> 0 | H9: ='[1]revenue receipt'!E7 -> 0 | I9: ='[1]revenue receipt'!F7 -> 176688.44 | J9: ='[1]revenue receipt'!G7 -> 28944.58 | K9: ='[1]revenue receipt'!H7 -> 9125.21 | L9: ='[1]revenue receipt'!I7 -> 7251.43 | ... Q9: ='[1]revenue receipt'!N7 -> 0
A10: Revenue Receipts | B10: Revenue Receipts | C10: Tax Revenue - GST | D10: GST Compensation Cess | E10: ='[1]revenue receipt'!B8 -> 0 | F10: ='[1]revenue receipt'!C8 -> 0 | G10: ='[1]revenue receipt'!D8 -> 0 | H10: ='[1]revenue receipt'!E8 -> 0 | I10: ='[1]revenue receipt'!F8 -> 62611.59 | J10: ='[1]revenue receipt'!G8 -> 95080.71 | K10: ='[1]revenue receipt'!H8 -> 95553.09 | L10: ='[1]revenue receipt'!I8 -> 85191.91 | ... Q10: ='[1]revenue receipt'!N8 -> 167110
A11: Revenue Receipts | B11: Revenue Receipts | C11: Tax Revenue - Income & Expenditure | D11: Taxes on Income & Expenditure (Total) | E11: ='[1]revenue receipt'!B9 -> 632517.3 | F11: ='[1]revenue receipt'!C9 -> 687259.5 | G11: ='[1]revenue receipt'!D9 -> 733515.33 | H11: ='[1]revenue receipt'!E9 -> 840530.12 | I11: ='[1]revenue receipt'!F9 -> 990092.49 | J11: ='[1]revenue receipt'!G9 -> 1125047 | K11: ='[1]revenue receipt'!H9 -> 1037155 | L11: ='[1]revenue receipt'!I9 -> 927935.69 | ... Q11: ='[1]revenue receipt'!N9 -> 2442000
A12: Revenue Receipts | B12: Revenue Receipts | C12: Tax Revenue - Income & Expenditure | D12: Corporation Tax | E12: ='[1]revenue receipt'!B10 -> 394677.85 | F12: ='[1]revenue receipt'!C10 -> 428924.74 | G12: ='[1]revenue receipt'!D10 -> 453228.33 | H12: ='[1]revenue receipt'!E10 -> 484923.86 | I12: ='[1]revenue receipt'!F10 -> 571201.87 | J12: ='[1]revenue receipt'!G10 -> 663571.62 | K12: ='[1]revenue receipt'!H10 -> 556875.55 | L12: ='[1]revenue receipt'!I10 -> 457718.97 | ... Q12: ='[1]revenue receipt'!N10 -> 1082000
A13: Revenue Receipts | B13: Revenue Receipts | C13: Tax Revenue - Income & Expenditure | D13: Income Tax (excl. Corp Tax) | E13: ='[1]revenue receipt'!B11 -> 237817.23 | F13: ='[1]revenue receipt'!C11 -> 258325.65 | G13: ='[1]revenue receipt'!D11 -> 280322.5 | H13: ='[1]revenue receipt'!E11 -> 340504.5 | I13: ='[1]revenue receipt'!F11 -> 408091.43 | J13: ='[1]revenue receipt'!G11 -> 461487.51 | K13: ='[1]revenue receipt'!H11 -> 480348.14 | L13: ='[1]revenue receipt'!I11 -> 470391.24 | ... Q13: ='[1]revenue receipt'!N11 -> 1357000
A14: Revenue Receipts | B14: Revenue Receipts | C14: Tax Revenue - Property & Capital | D14: Taxes on Property & Capital Transactions | E14: ='[1]revenue receipt'!B16 -> 6025.37 | F14: ='[1]revenue receipt'!C16 -> 8484.36 | G14: ='[1]revenue receipt'!D16 -> 8429.38 | H14: ='[1]revenue receipt'!E16 -> 9183.26 | I14: ='[1]revenue receipt'!F16 -> 11944.83 | J14: ='[1]revenue receipt'!G16 -> 11568.36 | K14: ='[1]revenue receipt'!H16 -> 12394.04 | L14: ='[1]revenue receipt'!I16 -> 16938.84 | ... Q14: ='[1]revenue receipt'!N16 -> 78000
A15: Revenue Receipts | B15: Revenue Receipts | C15: Tax Revenue - Property & Capital | D15: Securities Transaction Tax | E15: ='[1]revenue receipt'!B21 -> 5017.5 | F15: ='[1]revenue receipt'!C21 -> 7398.15 | G15: ='[1]revenue receipt'!D21 -> 7350.12 | H15: ='[1]revenue receipt'!E21 -> 8998.12 | I15: ='[1]revenue receipt'!F21 -> 11881.4 | J15: ='[1]revenue receipt'!G21 -> 11527.5 | K15: ='[1]revenue receipt'!H21 -> 12374.23 | L15: ='[1]revenue receipt'!I21 -> 16926.99 | ... Q15: ='[1]revenue receipt'!N21 -> 78000
A16: Revenue Receipts | B16: Revenue Receipts | C16: Tax Revenue - Commodities & Services | D16: Taxes on Commodities & Services (excl GST) | E16: ='[1]revenue receipt'!B22 -> 497322.97 | F16: ='[1]revenue receipt'!C22 -> 546188.14 | G16: ='[1]revenue receipt'!D22 -> 710068.12 | H16: ='[1]revenue receipt'!E22 -> 862109.13 | I16: ='[1]revenue receipt'!F22 -> 469864.1 | J16: ='[1]revenue receipt'!G22 -> 356698.37 | K16: ='[1]revenue receipt'!H22 -> 355926.17 | L16: ='[1]revenue receipt'!I22 -> 528115.66 | ... Q16: ='[1]revenue receipt'!N22 -> 562100
A17: Revenue Receipts | B17: Revenue Receipts | C17: Tax Revenue - Commodities & Services | D17: Customs | E17: ='[1]revenue receipt'!B24 -> 172085.42 | F17: ='[1]revenue receipt'!C24 -> 188016.19 | G17: ='[1]revenue receipt'!D24 -> 210338 | H17: ='[1]revenue receipt'!E24 -> 225370.34 | I17: ='[1]revenue receipt'!F24 -> 129029.92 | J17: ='[1]revenue receipt'!G24 -> 117812.85 | K17: ='[1]revenue receipt'!H24 -> 109282.54 | L17: ='[1]revenue receipt'!I24 -> 134750.39 | ... Q17: ='[1]revenue receipt'!N24 -> 240000
A18: Revenue Receipts | B18: Revenue Receipts | C18: Tax Revenue - Commodities & Services | D18: Union Excise Duties | E18: ='[1]revenue receipt'!B25 -> 169455.14 | F18: ='[1]revenue receipt'!C25 -> 188127.6 | G18: ='[1]revenue receipt'!D25 -> 287148.55 | H18: ='[1]revenue receipt'!E25 -> 380495.43 | I18: ='[1]revenue receipt'!F25 -> 258635.93 | J18: ='[1]revenue receipt'!G25 -> 230992.59 | K18: ='[1]revenue receipt'!H25 -> 239452.43 | L18: ='[1]revenue receipt'!I25 -> 389667.08 | ... Q18: ='[1]revenue receipt'!N25 -> 317000
A19: Revenue Receipts | B19: Revenue Receipts | C19: Tax Revenue - Commodities & Services | D19: Service Tax | E19: ='[1]revenue receipt'!B27 -> 154778.12 | F19: ='[1]revenue receipt'!C27 -> 167969.04 | G19: ='[1]revenue receipt'!D27 -> 211414.25 | H19: ='[1]revenue receipt'!E27 -> 254498.74 | I19: ='[1]revenue receipt'!F27 -> 81228.07 | J19: ='[1]revenue receipt'!G27 -> 6903.62 | K19: ='[1]revenue receipt'!H27 -> 6029.11 | L19: ='[1]revenue receipt'!I27 -> 1614.84 | ... Q19: ='[1]revenue receipt'!N27 -> 100
A20: Revenue Receipts | B20: Revenue Receipts | C20: Non-Tax Revenue | D20: Total Non-Tax Revenue | E20: ='[1]revenue receipt'!B119 -> 397032.9 | F20: ='[1]revenue receipt'!C119 -> 421581.66 | G20: ='[1]revenue receipt'!D119 -> 486462.09 | H20: ='[1]revenue receipt'!E119 -> 508020.25 | I20: ='[1]revenue receipt'!F119 -> 444964.86 | J20: ='[1]revenue receipt'!G119 -> 487451.63 | K20: ='[1]revenue receipt'!H119 -> 588701.25 | L20: ='[1]revenue receipt'!I119 -> 432406.39 | ... Q20: ='[1]revenue receipt'!N119 -> 987479.63
A21: Revenue Receipts | B21: Revenue Receipts | C21: Non-Tax Revenue - Fiscal Services | D21: Fiscal Services | E21: ='[1]revenue receipt'!B35 -> 883.77 | F21: ='[1]revenue receipt'!C35 -> 1393.59 | G21: ='[1]revenue receipt'!D35 -> 630.14 | H21: ='[1]revenue receipt'!E35 -> 764.85 | I21: ='[1]revenue receipt'!F35 -> 460.13 | J21: ='[1]revenue receipt'!G35 -> 743.71 | K21: ='[1]revenue receipt'!H35 -> 1041.06 | L21: ='[1]revenue receipt'!I35 -> 1168.8 | ... Q21: ='[1]revenue receipt'!N35 -> 2318.68
A22: Revenue Receipts | B22: Revenue Receipts | C22: Non-Tax Revenue - Interest & Dividends | D22: Interest Receipts, Dividends & Profits | E22: ='[1]revenue receipt'!B38 -> 134425.87 | F22: ='[1]revenue receipt'!C38 -> 137818.23 | G22: ='[1]revenue receipt'!D38 -> 158405.84 | H22: ='[1]revenue receipt'!E38 -> 166478.07 | I22: ='[1]revenue receipt'!F38 -> 137085.12 | J22: ='[1]revenue receipt'!G38 -> 140564.19 | K22: ='[1]revenue receipt'!H38 -> 243083.32 | L22: ='[1]revenue receipt'!I38 -> 156406.51 | ... Q22: ='[1]revenue receipt'!N38 -> 415237.98
A23: Revenue Receipts | B23: Revenue Receipts | C23: Non-Tax Revenue - Interest & Dividends | D23: Interest Receipts | E23: ='[1]revenue receipt'!B39 -> 43991.35 | F23: ='[1]revenue receipt'!C39 -> 47985.19 | G23: ='[1]revenue receipt'!D39 -> 46278.69 | H23: ='[1]revenue receipt'!E39 -> 43461.52 | I23: ='[1]revenue receipt'!F39 -> 45724.65 | J23: ='[1]revenue receipt'!G39 -> 27143.68 | K23: ='[1]revenue receipt'!H39 -> 56950.78 | L23: ='[1]revenue receipt'!I39 -> 59528.76 | ... Q23: ='[1]revenue receipt'!N39 -> 90237.98
A24: Revenue Receipts | B24: Revenue Receipts | C24: Non-Tax Revenue - Interest & Dividends | D24: Dividends and Profits | E24: ='[1]revenue receipt'!B43 -> 90434.52 | F24: ='[1]revenue receipt'!C43 -> 89833.04 | G24: ='[1]revenue receipt'!D43 -> 112127.15 | H24: ='[1]revenue receipt'!E43 -> 123016.55 | I24: ='[1]revenue receipt'!F43 -> 91360.47 | J24: ='[1]revenue receipt'!G43 -> 113420.51 | K24: ='[1]revenue receipt'!H43 -> 186132.54 | L24: ='[1]revenue receipt'!I43 -> 96877.75 | ... Q24: ='[1]revenue receipt'!N43 -> 325000
A25: Revenue Receipts | B25: Revenue Receipts | C25: Non-Tax Revenue - Other | D25: Other Non-Tax Revenue | E25: ='[1]revenue receipt'!B44 -> 114891.32 | F25: ='[1]revenue receipt'!C44 -> 119752.71 | G25: ='[1]revenue receipt'!D44 -> 325544.88 | H25: ='[1]revenue receipt'!E44 -> 339477.74 | I25: ='[1]revenue receipt'!F44 -> 303837.41 | J25: ='[1]revenue receipt'!G44 -> 345080.54 | K25: ='[1]revenue receipt'!H44 -> 344203.9 | L25: ='[1]revenue receipt'!I44 -> 273079.44 | ... Q25: ='[1]revenue receipt'!N44 -> 568748.44
A26: Revenue Receipts | B26: Revenue Receipts | C26: Non-Tax Revenue - Other | D26: NTR: General Services | E26: ='[1]revenue receipt'!B45 -> 28956.11 | F26: ='[1]revenue receipt'!C45 -> 35319.99 | G26: ='[1]revenue receipt'!D45 -> 35513.32 | H26: ='[1]revenue receipt'!E45 -> 40652.03 | I26: ='[1]revenue receipt'!F45 -> 42065.18 | J26: ='[1]revenue receipt'!G45 -> 47322.8 | K26: ='[1]revenue receipt'!H45 -> 45845.22 | L26: ='[1]revenue receipt'!I45 -> 39565.88 | ... Q26: ='[1]revenue receipt'!N45 -> 72257.03
A27: Revenue Receipts | B27: Revenue Receipts | C27: Non-Tax Revenue - Other | D27: NTR: Social & Community Services | E27: ='[1]revenue receipt'!B61 -> 1263.88 | F27: ='[1]revenue receipt'!C61 -> 1674.87 | G27: ='[1]revenue receipt'!D61 -> 10015.1 | H27: ='[1]revenue receipt'!E61 -> 11928.15 | I27: ='[1]revenue receipt'!F61 -> 3008.13 | J27: ='[1]revenue receipt'!G61 -> 3079.9 | K27: ='[1]revenue receipt'!H61 -> 3404.2 | L27: ='[1]revenue receipt'!I61 -> 3790.65 | ... Q27: ='[1]revenue receipt'!N61 -> 11187.46
A28: Revenue Receipts | B28: Revenue Receipts | C28: Non-Tax Revenue - Other | D28: NTR: Economic Services | E28: ='[1]revenue receipt'!B73 -> 226411.08 | F28: ='[1]revenue receipt'!C73 -> 242412.84 | G28: ='[1]revenue receipt'!D73 -> 278478.19 | H28: ='[1]revenue receipt'!E73 -> 285093.53 | I28: ='[1]revenue receipt'!F73 -> 256874.48 | J28: ='[1]revenue receipt'!G73 -> 292788.31 | K28: ='[1]revenue receipt'!H73 -> 293192.67 | L28: ='[1]revenue receipt'!I73 -> 228124.6 | ... Q28: ='[1]revenue receipt'!N73 -> 481884.77
A29: Revenue Receipts | B29: Revenue Receipts | C29: Non-Tax Revenue - Other | D29: NTR: Postal Receipts | E29: ='[1]revenue receipt'!B105 -> 10730.42 | F29: ='[1]revenue receipt'!C105 -> 11635.98 | G29: ='[1]revenue receipt'!D105 -> 12939.79 | H29: ='[1]revenue receipt'!E105 -> 11511 | I29: ='[1]revenue receipt'!F105 -> 12832.76 | J29: ='[1]revenue receipt'!G105 -> 13195.68 | K29: ='[1]revenue receipt'!H105 -> 13558.2 | L29: ='[1]revenue receipt'!I105 -> 10632.31 | ... Q29: ='[1]revenue receipt'!N105 -> 12487.11
A30: Revenue Receipts | B30: Revenue Receipts | C30: Non-Tax Revenue - Other | D30: NTR: Other Communication Services | E30: ='[1]revenue receipt'!B106 -> 40113.76 | F30: ='[1]revenue receipt'!C106 -> 30624.18 | G30: ='[1]revenue receipt'!D106 -> 56478.61 | H30: ='[1]revenue receipt'!E106 -> 70241.14 | I30: ='[1]revenue receipt'!F106 -> 32065.9 | J30: ='[1]revenue receipt'!G106 -> 40815.73 | K30: ='[1]revenue receipt'!H106 -> 69846.43 | L30: ='[1]revenue receipt'!I106 -> 45500.65 | ... Q30: ='[1]revenue receipt'!N106 -> 82442.84
A31: Revenue Receipts | B31: Revenue Receipts | C31: Grants-in-Aid | D31: Grants-in-Aid & Contributions | E31: ='[1]revenue receipt'!B116 -> 3618.06 | F31: ='[1]revenue receipt'!C116 -> 1599.88 | G31: ='[1]revenue receipt'!D116 -> 1881.23 | H31: ='[1]revenue receipt'!E116 -> 1299.59 | I31: ='[1]revenue receipt'!F116 -> 3582.2 | J31: ='[1]revenue receipt'!G116 -> 1063.19 | K31: ='[1]revenue receipt'!H116 -> 372.97 | L31: ='[1]revenue receipt'!I116 -> 1751.64 | ... Q31: ='[1]revenue receipt'!N116 -> 1174.53
A32: Revenue Expenditure | B32: Revenue Expenditure | C32: TOTAL | D32: Total Revenue Expenditure | E32: ='[1]revenue receipt'!B122 -> 1575096.6 | F32: ='[1]revenue receipt'!C122 -> 1695136.8 | G32: ='[1]revenue receipt'!D122 -> 1779528.8 | H32: ='[1]revenue receipt'!E122 -> 1933018.1 | I32: ='[1]revenue receipt'!F122 -> 2140084.5 | J32: ='[1]revenue receipt'!G122 -> 2261570.8 | K32: ='[1]revenue receipt'!H122 -> 2615319.7 | L32: ='[1]revenue receipt'!I122 -> 3314851.9 | ... Q32: ='[1]revenue receipt'!N122 -> 4359702.4
A33: Revenue Expenditure | B33: Revenue Expenditure | C33: General Services | D33: General Services (Total) | E33: ='[1]revenue disbursements '!B3 -> 678742.7 | F33: ='[1]revenue disbursements '!C3 -> 751667.18 | G33: ='[1]revenue disbursements '!D3 -> 803420.84 | H33: ='[1]revenue disbursements '!E3 -> 924736.15 | I33: ='[1]revenue disbursements '!F3 -> 1008488.6 | J33: ='[1]revenue disbursements '!G3 -> 1100283 | K33: ='[1]revenue disbursements '!H3 -> 1210584.8 | L33: ='[1]revenue disbursements '!I3 -> 1294769.2 | ... Q33: ='[1]revenue disbursements '!N3 -> 2182279.6
A34: Revenue Expenditure | B34: Revenue Expenditure | C34: General Services | D34: Organs of State | E34: ='[1]revenue disbursements '!B4 -> 5044.48 | F34: ='[1]revenue disbursements '!C4 -> 5213.82 | G34: ='[1]revenue disbursements '!D4 -> 7300.44 | H34: ='[1]revenue disbursements '!E4 -> 8664.35 | I34: ='[1]revenue disbursements '!F4 -> 7936.69 | J34: ='[1]revenue disbursements '!G4 -> 8538.68 | K34: ='[1]revenue disbursements '!H4 -> 9295.48 | L34: ='[1]revenue disbursements '!I4 -> 8008.86 | ... Q34: ='[1]revenue disbursements '!N4 -> 12737.04
A35: Revenue Expenditure | B35: Revenue Expenditure | C35: General Services | D35: Tax Collection | E35: ='[1]revenue disbursements '!B11 -> 8464 | F35: ='[1]revenue disbursements '!C11 -> 9593.38 | G35: ='[1]revenue disbursements '!D11 -> 10648.57 | H35: ='[1]revenue disbursements '!E11 -> 13000.46 | I35: ='[1]revenue disbursements '!F11 -> 15361.52 | J35: ='[1]revenue disbursements '!G11 -> 16536.59 | K35: ='[1]revenue disbursements '!H11 -> 16834.72 | L35: ='[1]revenue disbursements '!I11 -> 17019.76 | ... Q35: ='[1]revenue disbursements '!N11 -> 55177.64
A36: Revenue Expenditure | B36: Revenue Expenditure | C36: General Services | D36: Interest Payment & Servicing of Debt | E36: ='[1]revenue disbursements '!B20 -> 395199.59 | F36: ='[1]revenue disbursements '!C20 -> 425098.26 | G36: ='[1]revenue disbursements '!D20 -> 457270.38 | H36: ='[1]revenue disbursements '!E20 -> 504512.46 | I36: ='[1]revenue disbursements '!F20 -> 543707.26 | J36: ='[1]revenue disbursements '!G20 -> 595552.17 | K36: ='[1]revenue disbursements '!H20 -> 655370.53 | L36: ='[1]revenue disbursements '!I20 -> 720983.93 | ... Q36: ='[1]revenue disbursements '!N20 -> 1315838
A37: Revenue Expenditure | B37: Revenue Expenditure | C37: General Services | D37: Interest Payments | E37: ='[1]revenue disbursements '!B22 -> 394512.11 | F37: ='[1]revenue disbursements '!C22 -> 425098.26 | G37: ='[1]revenue disbursements '!D22 -> 457232.16 | H37: ='[1]revenue disbursements '!E22 -> 503919.04 | I37: ='[1]revenue disbursements '!F22 -> 543404.14 | J37: ='[1]revenue disbursements '!G22 -> 595530.24 | K37: ='[1]revenue disbursements '!H22 -> 649879.87 | L37: ='[1]revenue disbursements '!I22 -> 711936.57 | ... Q37: ='[1]revenue disbursements '!N22 -> 1313488
A38: Revenue Expenditure | B38: Revenue Expenditure | C38: General Services | D38: Administrative Services | E38: ='[1]revenue disbursements '!B23 -> 52479.96 | F38: ='[1]revenue disbursements '!C23 -> 58552.91 | G38: ='[1]revenue disbursements '!D23 -> 65051.15 | H38: ='[1]revenue disbursements '!E23 -> 76186.88 | I38: ='[1]revenue disbursements '!F23 -> 85190.03 | J38: ='[1]revenue disbursements '!G23 -> 98577.47 | K38: ='[1]revenue disbursements '!H23 -> 109586.86 | L38: ='[1]revenue disbursements '!I23 -> 105083.76 | ... Q38: ='[1]revenue disbursements '!N23 -> 170552.75
A39: Revenue Expenditure | B39: Revenue Expenditure | C39: General Services | D39: Police | E39: ='[1]revenue disbursements '!B26 -> 42994.76 | F39: ='[1]revenue disbursements '!C26 -> 47943.3 | G39: ='[1]revenue disbursements '!D26 -> 53015.02 | H39: ='[1]revenue disbursements '!E26 -> 62732.88 | I39: ='[1]revenue disbursements '!F26 -> 69472.6 | J39: ='[1]revenue disbursements '!G26 -> 80406.35 | K39: ='[1]revenue disbursements '!H26 -> 89866.55 | L39: ='[1]revenue disbursements '!I26 -> 86793.01 | ... Q39: ='[1]revenue disbursements '!N26 -> 141879.63
A40: Revenue Expenditure | B40: Revenue Expenditure | C40: General Services | D40: Pensions & Misc General Services | E40: ='[1]revenue disbursements '!B34 -> 87551.62 | F40: ='[1]revenue disbursements '!C34 -> 107910.62 | G40: ='[1]revenue disbursements '!D34 -> 111285.34 | H40: ='[1]revenue disbursements '!E34 -> 149236.97 | I40: ='[1]revenue disbursements '!F34 -> 163195.74 | J40: ='[1]revenue disbursements '!G34 -> 176909.73 | K40: ='[1]revenue disbursements '!H34 -> 203877.44 | L40: ='[1]revenue disbursements '!I34 -> 227572.6 | ... Q40: ='[1]revenue disbursements '!N34 -> 308118.68
...

Sheet revenue receipts
A1: STATEMENT I - CONSOLIDATED FUND OF INDIA - REVENUE ACCOUNT - RECEIPTS
A2: Categories | B2: Actuals 2013-2014 | C2: Actuals 2014-2015 | D2: Actuals 2015-2016 | E2: Actuals 2016-2017 | F2: Actuals 2017-2018 | G2: Actuals 2018-2019 | H2: Actuals 2019-2020 | I2: Actuals 2020-2021 | J2: Actuals 2021-2022 | K2: Actuals 2022-2023 | L2: Actuals 2023-2024 | M2: Revised Estimates 2024-2025 | N2: Budget Estimates 2025-2026
A3: A. TAX REVENUE
A4: (a) Goods and Services Tax | B4: 0 | C4: 0 | D4: 0 | E4: 0 | F4: =SUM(F5:F8) -> 444196.53 | G4: =SUM(G5:G8) -> 584337.5 | H4: =SUM(H5:H8) -> 601783.88 | I4: 551541.51 | J4: 702412.82 | K4: 853900.57 | L4: 962704.98 | M4: 1066839 | N4: 1183355
A5: Central Goods and Services Tax (CGST) | B5: 0 | C5: 0 | D5: 0 | E5: 0 | F5: 203261.4 | G5: 457534.01 | H5: 494070.6 | I5: 456333.97 | J5: 591226.14 | K5: 718521.75 | L5: 820622.09 | M5: 908459 | N5: 1010890
A6: Union Territory Goods and Services Tax (UTGST) | B6: 0 | C6: 0 | D6: 0 | E6: 0 | F6: 1635.1 | G6: 2778.2 | H6: 3034.98 | I6: 2764.2 | J6: 4298.94 | K6: 4768.12 | L6: 5497.16 | M6: 4940 | N6: 5355
A7: Integrated Goods and Services Tax (IGST) | B7: 0 | C7: 0 | D7: 0 | E7: 0 | F7: 176688.44 | G7: 28944.58 | H7: 9125.21 | I7: 7251.43 | J7: 2119.08 | K7: 4748.29 | L7: -4850.43 | M7: 0 | N7: 0
A8: Goods and Services Tax Compensation Cess | B8: 0 | C8: 0 | D8: 0 | E8: 0 | F8: 62611.59 | G8: 95080.71 | H8: 95553.09 | I8: 85191.91 | J8: 104768.66 | K8: 125862.41 | L8: 141436.16 | M8: 153440 | N8: 167110
A9: (b) Taxes on Income and Expenditure | B9: 632517.3 | C9: 687259.5 | D9: 733515.33 | E9: 840530.12 | F9: 990092.49 | G9: 1125047 | H9: 1037155 | I9: 927935.69 | J9: 1385089.5 | K9: 1634008 | L9: 1922033.5 | M9: 2182000 | N9: 2442000
A10: Corporation Tax | B10: 394677.85 | C10: 428924.74 | D10: 453228.33 | E10: 484923.86 | F10: 571201.87 | G10: 663571.62 | H10: 556875.55 | I10: 457718.97 | J10: 712037.33 | K10: 825833.64 | L10: 911055.01 | M10: 980000 | N10: 1082000
A11: Taxes on Income Other Than Corporation Tax | B11: 237817.23 | C11: 258325.65 | D11: 280322.5 | E11: 340504.5 | F11: 408091.43 | G11: 461487.51 | H11: 480348.14 | I11: 470391.24 | J11: 673100.48 | K11: 808221.32 | L11: 1010947.8 | M11: 1199300 | N11: 1357000
A12: Hotel Receipts Tax | B12: 0.61 | C12: 0.94 | D12: 0.59 | E12: 0.48 | F12: 0.5 | G12: 0.44 | H12: 1.26 | I12: 0.3 | J12: 0.25 | K12: 0.66 | L12: 0.34 | M12: 0 | N12: 0
A13: Interest Tax | B13: 8 | C13: 5.58 | D13: 5.31 | E13: 4.98 | F13: 4.45 | G13: 3.19 | H13: 2.09 | I13: 2.36 | J13: 3.96 | K13: 8.46 | L13: 19.93 | M13: 0 | N13: 0
A14: Fringe Benefit Tax | B14: 4.71 | C14: -8.27 | D14: -45.82 | E14: -66.89 | F14: -93.29 | G14: -31.59 | H14: -135.27 | I14: -181.86 | J14: -54.98 | K14: -74.56 | L14: -4.46 | M14: 0 | N14: 0
A15: Other Taxes on Income and Expenditure | B15: 8.9 | C15: 10.86 | D15: 4.42 | E15: 15163.19 | F15: 10887.53 | G15: 15.81 | H15: 63.26 | I15: 4.68 | J15: 2.48 | K15: 18.51 | L15: 14.89 | M15: 2700 | N15: 3000
A16: (c) Taxes on Property and Capital Transactions | B16: =SUM(B18:B21) -> 6025.37 | C16: =SUM(C17:C21) -> 8484.36 | D16: =SUM(D17:D21) -> 8429.38 | E16: =SUM(E17:E21) -> 9183.26 | F16: =SUM(F17:F21) -> 11944.83 | G16: 11568.36 | H16: 12394.04 | I16: 16938.84 | J16: 23203.82 | K16: 25076.35 | L16: 33785.52 | M16: 55000 | N16: 78000
A17: Stamps and Registration Fees | B17: 0 | C17: … | D17: … | E17: 0 | F17: … | G17: … | H17: … | I17: … | J17: 0.46 | K17: 0.2 | L17: 0.31 | M17: 0 | N17: 0
A18: Gift tax | B18: 0.53 | C18: 0.49 | D18: 0 | E18: 0 | F18: 0 | G18: 0 | H18: 0 | I18: 0 | J18: 0 | K18: 0 | N18: 0
A19: Estate Duty | B19: 0.44 | C19: 0.22 | D19: 0.67 | E19: 0.67 | F19: 0.84 | G19: 1.12 | H19: 1.7 | I19: 1.38 | J19: 1.74 | K19: 1.06 | L19: 1.31 | M19: 0 | N19: 0
A20: Taxes on Wealth | B20: 1006.9 | C20: 1085.5 | D20: 1078.59 | E20: 184.47 | F20: 62.59 | G20: 39.74 | H20: 18.11 | I20: 10.47 | J20: 10.59 | K20: -10.28 | L20: 6.12 | M20: 0 | N20: 0
A21: Securities Transaction Tax | B21: 5017.5 | C21: 7398.15 | D21: 7350.12 | E21: 8998.12 | F21: 11881.4 | G21: 11527.5 | H21: 12374.23 | I21: 16926.99 | J21: 23191.03 | K21: 25085.37 | L21: 33777.78 | M21: 55000 | N21: 78000
A22: (d) Taxes on Commodities and Services other than Goods and Services Tax | B22: =SUM(B23:B28) -> 497322.97 | C22: =SUM(C23:C28) -> 546188.14 | D22: =SUM(D23:D28) -> 710068.12 | E22: =SUM(E23:E28) -> 862109.13 | F22: =SUM(F23:F28) -> 469864.1 | G22: =SUM(G23:G28) -> 356698.37 | H22: =SUM(H23:H28) -> 355926.17 | I22: 528115.66 | J22: 595383.93 | K22: 537263.52 | L22: 543249.51 | M22: 545100 | N22: 562100
A23: Banking Cash Transaction Tax | B23: 0.01 | C23: 0 | D23: 0 | E23: 0 | F23: 0.01 | G23: 0 | H23: … | I23: 1.89 | J23: 0.02 | K23: 736.3 | L23: 414.32 | M23: 0 | N23: 0
A24: Customs | B24: 172085.42 | C24: 188016.19 | D24: 210338 | E24: 225370.34 | F24: 129029.92 | G24: 117812.85 | H24: 109282.54 | I24: 134750.39 | J24: 199728.3 | K24: 213372.09 | L24: 233118.97 | M24: 235000 | N24: 240000
A25: Union Excise Duties | B25: 169455.14 | C25: 188127.6 | D25: 287148.55 | E25: 380495.43 | F25: 258635.93 | G25: 230992.59 | H25: 239452.43 | I25: 389667.08 | J25: 390808.07 | K25: 319000.11 | L25: 305362.18 | M25: 305000 | N25: 317000
A26: Sales Tax | B26: 0.75 | C26: 0.85 | D26: ... | E26: 0 | F26: 0 | G26: 0 | H26: ... | I26: ... | J26: 0 | K26: 0 | L26: 0 | M26: 0 | N26: 0
A27: Service Tax | B27: 154778.12 | C27: 167969.04 | D27: 211414.25 | E27: 254498.74 | F27: 81228.07 | G27: 6903.62 | H27: 6029.11 | I27: 1614.84 | J27: 1011.82 | K27: 430.77 | L27: 424.96 | M27: 100 | N27: 100
A28: Other Taxes and Duties on Commodities and Services | B28: 1003.53 | C28: 2074.46 | D28: 1167.32 | E28: 1744.62 | F28: 970.17 | G28: 989.31 | H28: 1162.09 | I28: 2081.46 | J28: 3835.72 | K28: 3724.25 | L28: 3929.08 | M28: 5000 | N28: 5000
A29: (e) Taxes of Union Territories without Legislature | B29: 3129.83 | C29: 3203.75 | D29: 3878.26 | E29: 4145.53 | F29: 3085.58 | G29: 2814.22 | H29: 2800.21 | I29: 2572.14 | J29: 3224.99 | K29: 3943.17 | L29: 3745.09 | M29: 4516.01 | N29: 4778
A30: GROSS TAX REVENUE | B30: 1138995.5 | C30: 1245135.8 | D30: 1455891.1 | E30: 1715968 | F30: 1919183.5 | G30: 2080465.4 | H30: 2010059.3 | I30: 2027103.8 | J30: 2709315.1 | K30: 3054191.6 | L30: 3465518.6 | M30: 3853455 | N30: 4270233
A31: State's share excluded from the Consolidated Fund | B31: 318229.58 | C31: 337808.45 | D31: 506192.96 | E31: 608000.31 | F31: 673005.29 | G31: 761454.15 | H31: 650677.05 | I31: 594996.76 | J31: 898391.57 | K31: 948405.82 | L31: 1129493.7 | M31: 1286885.4 | N31: 1422444.1
A32: Tax Revenue of the Central Government | B32: 820765.89 | C32: 907327.3 | D32: 949698.13 | E32: 1107967.7 | F32: 1246178.2 | G32: 1319011.3 | H32: 1359382.3 | I32: 1432107.1 | J32: 1810923.5 | K32: 2105785.8 | L32: 2336024.9 | M32: 2566569.6 | N32: 2847788.9
A34: B. NON-TAX REVENUE
A35: (a) Fiscal Services | B35: 883.77 | C35: 1393.59 | D35: 630.14 | E35: 764.85 | F35: 460.13 | G35: 743.71 | H35: 1041.06 | I35: 1168.8 | J35: 193.26 | K35: 1127.65 | L35: 1858.12 | M35: 1473.82 | N35: 2318.68
A36: Currency, Coinage and Mint | B36: 740.1 | C36: 1296.72 | D36: 547.2 | E36: 680.32 | F36: 282 | G36: 514.49 | H36: 659.98 | I36: 1093.16 | J36: 103.82 | K36: 443.36 | L36: 178.28 | M36: 133.4 | N36: 212.98
A37: Other Fiscal Services | B37: 143.67 | C37: 96.87 | D37: 82.94 | E37: 84.53 | F37: 178.13 | G37: 229.22 | H37: 381.08 | I37: 75.64 | J37: 89.44 | K37: 684.29 | L37: 1679.84 | M37: 1340.42 | N37: 2105.7
A38: (b) Interest Receipts, Dividends and Profits | B38: 134425.87 | C38: 137818.23 | D38: 158405.84 | E38: 166478.07 | F38: 137085.12 | G38: 140564.19 | H38: 243083.32 | I38: 156406.51 | J38: 206810.28 | K38: 159464.25 | L38: 249528.99 | M38: 372557.09 | N38: 415237.98
A39: Interest Receipts | B39: 43991.35 | C39: 47985.19 | D39: 46278.69 | E39: 43461.52 | F39: 45724.65 | G39: 27143.68 | H39: 56950.78 | I39: 59528.76 | J39: 46163.53 | K39: 59550.41 | L39: 78652.02 | M39: 83272.49 | N39: 90237.98
A40: Interest from State and Union Territory Governments | B40: 8985.11 | C40: 8366.75 | D40: 7858.83 | E40: 7608.36 | F40: 7357.71 | G40: 7402.57 | H40: 7696 | I40: 6316.9 | J40: 6552.18 | K40: 9702.26 | L40: 13641.26 | M40: 14041.86 | N40: 17580.82
A41: Interest from Railways | B41: 7982.94 | C41: 9147.82 | D41: 10144.43 | E41: … | F41: … | G41: … | H41: … | I41: … | J41: … | K41: … | N41: …
...

Sheet revenue disbursements
A1: STATEMENT I - CONSOLIDATED FUND OF INDIA - REVENUE ACCOUNT - DISBURSEMENTS
A2: Categories | B2: Actuals 2013-2014 | C2: Actuals 2014-2015 | D2: Actuals 2015-2016 | E2: Actuals 2016-2017 | F2: Actuals 2017-2018 | G2: Actuals 2018-2019 | H2: Actuals 2019-2020 | I2: Actuals 2020-2021 | J2: Actuals 2021-2022 | K2: Actuals 2022-2023 | L2: Actuals 2023-2024 | M2: Revised Estimates 2024-2025 | N2: Budget Estimates 2025-2026
A3: A. GENERAL SERVICES | B3: 678742.7 | C3: 751667.18 | D3: 803420.84 | E3: 924736.15 | F3: 1008488.6 | G3: 1100283 | H3: 1210584.8 | I3: 1294769.2 | J3: 1478491.1 | K3: 1677865.9 | L3: 1876063.4 | M3: 2042886.1 | N3: 2182279.6
A4: (a)Organs of State | B4: 5044.48 | C4: 5213.82 | D4: 7300.44 | E4: 8664.35 | F4: 7936.69 | G4: 8538.68 | H4: 9295.48 | I4: 8008.86 | J4: 10077.41 | K4: 12280.97 | L4: 13283.76 | M4: 14107.08 | N4: 12737.04
A5: Parliament/State/Union Territory Legislatures | B5: 794.76 | C5: 754.14 | D5: 835.67 | E5: 920.48 | F5: 948.39 | G5: 1085.86 | H5: 1036.14 | I5: 906.3 | J5: 962.52 | K5: 1049.72 | L5: 1082.48 | M5: 1215.35 | N5: 1278.99
A6: President, Vice President/Governor, Administrator of Union Territories | B6: 42.26 | C6: 45.77 | D6: 57.45 | E6: 61.59 | F6: 62.18 | G6: 67.51 | H6: 78.64 | I6: 75.81 | J6: 76.05 | K6: 89.97 | L6: 99.58 | M6: 132.78 | N6: 139.54
A7: Council of Ministers | B7: 369.36 | C7: 438.25 | D7: 668.75 | E7: 601.34 | F7: 604.52 | G7: 862.79 | H7: 884.85 | I7: 1181.01 | J7: 1300.38 | K7: 954.15 | L7: 876.11 | M7: 676.3 | N7: 761.97
A8: Administration of Justice | B8: 395.07 | C8: 395.16 | D8: 621.88 | E8: 856.68 | F8: 963.58 | G8: 908.81 | H8: 876.31 | I8: 853.4 | J8: 862.95 | K8: 891.86 | L8: 1946.21 | M8: 2265.34 | N8: 2617.25
A9: Elections | B9: 711.47 | C9: 580.65 | D9: 1926.26 | E9: 2453.3 | F9: 1322.22 | G9: 1130.18 | H9: 1624.39 | I9: 259.82 | J9: 1852.79 | K9: 3775.42 | L9: 3535.06 | M9: 3732.03 | N9: 1700.88
A10: Audit | B10: 2731.56 | C10: 2999.85 | D10: 3190.43 | E10: 3770.96 | F10: 4035.8 | G10: 4483.53 | H10: 4795.15 | I10: 4732.52 | J10: 5022.72 | K10: 5519.85 | L10: 5744.32 | M10: 6085.28 | N10: 6238.41
A11: (b)Tax Collection | B11: 8464 | C11: 9593.38 | D11: 10648.57 | E11: 13000.46 | F11: 15361.52 | G11: 16536.59 | H11: 16834.72 | I11: 17019.76 | J11: 67395.6 | K11: 45640.91 | L11: 45881.6 | M11: 51775.99 | N11: 55177.64
A12: Collection of Taxes on Income and Expenditure | B12: 3596.27 | C12: 4045.03 | D12: 4573.06 | E12: 5483.64 | F12: 6019.34 | G12: 6991.43 | H12: 6878.02 | I12: 7138.51 | J12: 7393.75 | K12: 8354.75 | L12: 8546.6 | M12: 9103.65 | N12: 9374.88
A13: Collection of Taxes on Wealth, Securities Transaction Tax and Other Taxes | B13: 91.04 | C13: 102.53 | D13: 115.51 | E13: 139.46 | F13: 152.17 | G13: 176.85 | H13: 173.81 | I13: 180.59 | J13: 186.97 | K13: 211.3 | L13: 215.84 | M13: 230.06 | N13: 236.83
A14: Customs | B14: 2142.06 | C14: 2496.06 | D14: 2798.35 | E14: 3321.58 | F14: 3941.02 | G14: 4418.62 | H14: 4634.16 | I14: 4611.14 | J14: 54452.36 | K14: 31104.11 | L14: 31243.36 | M14: 35935.82 | N14: 38695.41
A15: Union Excise Duties | B15: 2634.63 | C15: 2949.76 | D15: 3161.65 | E15: 4055.78 | F15: 5248.99 | G15: 0 | H15: 0 | I15: 0 | J15: 0 | K15: 0
A16: Collection Charges under Central Goods and Services Tax and Integrated Goods and Services Tax | B16: … | C16: … | D16: 0 | E16: 0 | F16: 0 | G16: 4949.69 | H16: 5148.73 | I16: 5089.52 | J16: 5362.52 | K16: 5970.75 | L16: 5875.8 | M16: 6506.46 | N16: 6870.52
A17: (c)Other Fiscal Services | B17: 112.84 | C17: 152.24 | D17: 265.49 | E17: 109.99 | F17: 232.14 | G17: 285.79 | H17: 322.53 | I17: 586.61 | J17: 583.77 | K17: 660.58 | L17: 1162.13 | M17: 1241.49 | N17: 1131.97
A18: Currency, Coinage and Mint | B18: 0.5 | C18: … | D18: … | E18: … | F18: … | G18: … | H18: … | I18: … | J18: … | K18: … | L18: … | M18: … | N18: …
A19: Other Fiscal Services | B19: 112.34 | C19: 152.24 | D19: 265.49 | E19: 109.99 | F19: 232.14 | G19: 285.79 | H19: 322.53 | I19: 586.61 | J19: 583.77 | K19: 660.58 | L19: 1162.13 | M19: 1241.49 | N19: 1131.97
A20: (d)Interest Payment and Servicing of Debt | B20: 395199.59 | C20: 425098.26 | D20: 457270.38 | E20: 504512.46 | F20: 543707.26 | G20: 595552.17 | H20: 655370.53 | I20: 720983.93 | J20: 828252.59 | K20: 958715.21 | L20: 1102650.2 | M20: 1185170.9 | N20: 1315838
A21: Appropriation for Reduction or Avoidance of Debt | B21: 687.48 | C21: ... | D21: 38.22 | E21: 593.42 | F21: 303.12 | G21: 21.93 | H21: 5490.66 | I21: 9047.36 | J21: 5241.31 | K21: 1025.68 | L21: 782.3 | M21: 2660.59 | N21: 2350
A22: Interest Payments | B22: 394512.11 | C22: 425098.26 | D22: 457232.16 | E22: 503919.04 | F22: 543404.14 | G22: 595530.24 | H22: 649879.87 | I22: 711936.57 | J22: 823011.28 | K22: 957689.53 | L22: 1101867.9 | M22: 1182510.3 | N22: 1313488
A23: (e)Administrative Services | B23: 52479.96 | C23: 58552.91 | D23: 65051.15 | E23: 76186.88 | F23: 85190.03 | G23: 98577.47 | H23: 109586.86 | I23: 105083.76 | J23: 118244.14 | K23: 130975.55 | L23: 141804.86 | M23: 164840.58 | N23: 170552.75
A24: Public Service Commission | B24: 269.89 | C24: 313.33 | D24: 356.81 | E24: 354.64 | F24: 589.11 | G24: 423.16 | H24: 620.01 | I24: 665.16 | J24: 741.88 | K24: 897.51 | L24: 1020.99 | M24: 989.1 | N24: 927.27
A25: Secretariat-General Services | B25: 2597.86 | C25: 2887.84 | D25: 3335 | E25: 4066.53 | F25: 4592.66 | G25: 6721.37 | H25: 7141.77 | I25: 7100.07 | J25: 8043.09 | K25: 9805.67 | L25: 10614.95 | M25: 11610.23 | N25: 11382.29
A26: Police | B26: 42994.76 | C26: 47943.3 | D26: 53015.02 | E26: 62732.88 | F26: 69472.6 | G26: 80406.35 | H26: 89866.55 | I26: 86793.01 | J26: 98283.92 | K26: 107186.53 | L26: 115392.83 | M26: 136306.43 | N26: 141879.63
A27: Jails | B27: 0.81 | C27: 0.5 | D27: 0.85 | E27: 1 | F27: 1.7 | G27: 0.55 | H27: 1 | I27: 1 | J27: 1 | K27: 1 | L27: 1.3 | M27: 5 | N27: 5
A28: Supplies and Disposals | B28: 96.91 | C28: 136.95 | D28: 121.99 | E28: 137.73 | F28: 176.41 | G28: 25 | H28: 50 | I28: 23.84 | J28: 0 | K28: … | L28: … | M28: … | N28: …
A29: Stationery and Printing | B29: 63.55 | C29: 90.47 | D29: 65.14 | E29: 113.75 | F29: 98.99 | G29: 81.55 | H29: 80.73 | I29: 63.61 | J29: 46.58 | K29: 70.08 | L29: 75.44 | M29: 85.6 | N29: 100.72
A30: Public Works | B30: 1444.04 | C30: 1565.43 | D30: 1595.26 | E30: 1774.97 | F30: 1921.56 | G30: 1910.5 | H30: 1957.29 | I30: 1948.11 | J30: 2013.49 | K30: 2155.64 | L30: 2087.9 | M30: 2296.19 | N30: 2436.61
A31: External Affairs | B31: 4450.3 | C31: 4970.66 | D31: 5871.09 | E31: 6261.45 | F31: 7605.74 | G31: 8202.14 | H31: 9021.35 | I31: 7751.76 | J31: 8337.8 | K31: 9950.86 | L31: 11586.41 | M31: 12255.58 | N31: 12468.27
A32: Vigilance | B32: ... | C32: 20.84 | D32: 24.21 | E32: 27.68 | F32: 31.03 | G32: 33.98 | H32: 51.51 | I32: 47.07 | J32: 53.17 | K32: 59.36 | L32: 60.22 | M32: 73.82 | N32: 81.63
A33: Other Administrative Services | B33: 561.84 | C33: 623.59 | D33: 665.78 | E33: 716.25 | F33: 700.23 | G33: 772.87 | H33: 796.65 | I33: 690.13 | J33: 723.21 | K33: 848.9 | L33: 964.82 | M33: 1218.63 | N33: 1271.33
A34: (f)Pensions and Miscellaneous General Services | B34: 87551.62 | C34: 107910.62 | D34: 111285.34 | E34: 149236.97 | F34: 163195.74 | G34: 176909.73 | H34: 203877.44 | I34: 227572.6 | J34: 218981.69 | K34: 265359.82 | L34: 273542.41 | M34: 320886.63 | N34: 308118.68
A35: Pensions and other Retirement Benefits | B35: 74896.19 | C35: 93610.72 | D35: 96770.94 | E35: 131400.85 | F35: 145745.07 | G35: 160211.49 | H35: 183954.61 | I35: 208473.04 | J35: 198946.1 | K35: 241599.29 | L35: 238328.29 | M35: 276102.9 | N35: 277618.32
A36: Miscellaneous General Services | B36: 12655.43 | C36: 14299.9 | D36: 14514.4 | E36: 17836.12 | F36: 17450.67 | G36: 16698.24 | H36: 19922.83 | I36: 19099.56 | J36: 20035.59 | K36: 23760.53 | L36: 35214.12 | M36: 44783.73 | N36: 30500.36
A37: (g)Defence Services | B37: 129890.21 | C37: 145145.95 | D37: 151599.47 | E37: 173025.04 | F37: 192865.24 | G37: 203882.56 | H37: 215297.28 | I37: 215513.72 | J37: 234955.86 | K37: 264232.91 | L37: 297738.47 | M37: 304863.41 | N37: 318723.58
A38: Defence Services - Army | B38: 87750.54 | C38: 99321.39 | D38: 105994.58 | E38: 120374.48 | F38: 135362.36 | G38: 141829.61 | H38: 146821.92 | I38: 145181.03 | J38: 161728.27 | K38: 175666.05 | L38: 197020.12 | M38: 204628.97 | N38: 212030.78
A39: Defence Services - Navy | B39: 13472.26 | C39: 14352 | D39: 15320.81 | E39: 17469.27 | F39: 19344.87 | G39: 21738.88 | H39: 23087.69 | I39: 24710.34 | J39: 24426.52 | K39: 31343.6 | L39: 35147.8 | M39: 36557.31 | N39: 39019.8
A40: Defence Services - Air Force | B40: 20160.27 | C40: 22685.3 | D40: 21848.9 | E40: 25228.14 | F40: 28418.8 | G40: 29370.54 | H40: 31528.49 | I40: 34615.96 | J40: 35687.93 | K40: 47455.55 | L40: 54742.33 | M40: 51876.77 | N40: 55000
...

Sheet capital receipts
A1: STATEMENT I - CONSOLIDATED FUND OF INDIA - CAPITAL ACCOUNT - RECEIPT
